Workbook

Sheet 育龄妇女TFR
A1: 指标名称 | B1: 抽样数:占总人口比例:女性:15-19岁 | C1: 抽样数:占总人口比例:女性:20-24岁 | D1: 抽样数:占总人口比例:女性:25-29岁 | E1: 抽样数:占总人口比例:女性:30-34岁 | F1: 抽样数:占总人口比例:女性:35-39岁 | G1: 抽样数:占总人口比例:女性:40-44岁 | H1: 抽样数:占总人口比例:女性:45-49岁 | I1: 总人数 | J1: 出生人口 | K1: TFR | L1: 根据七普数据调整的出生人口 | M1: 根据七普数据调整的TFR
A2: 37986 | B2: =分年龄阶段人口!AS2 -> 5169.08 | C2: =分年龄阶段人口!AT2 -> 4380.7953 | D2: =分年龄阶段人口!AU2 -> 4923.5487 | E2: =分年龄阶段人口!AV2 -> 6241.6641 | F2: =分年龄阶段人口!AW2 -> 6138.2825 | G2: =分年龄阶段人口!AX2 -> 5039.853 | H2: =分年龄阶段人口!AY2 -> 4781.399 | I2: =SUM(B2:H2) -> 36674.623 | J2: =出生人口!B58 -> 1599 | K2: =J2*30/I2 -> 1.3079889
A3: 38352 | B3: =分年龄阶段人口!AS3 -> 5459.496 | C3: =分年龄阶段人口!AT3 -> 4198.6124 | D3: =分年龄阶段人口!AU3 -> 4666.5692 | E3: =分年龄阶段人口!AV3 -> 6109.436 | F3: =分年龄阶段人口!AW3 -> 6330.4156 | G3: =分年龄阶段人口!AX3 -> 5212.5188 | H3: =分年龄阶段人口!AY3 -> 4588.5764 | I3: =SUM(B3:H3) -> 36565.624 | J3: =出生人口!B59 -> 1593 | K3: =J3*30/I3 -> 1.3069652
A4: 38717 | B4: =分年龄阶段人口!AS4 -> 5347.9204 | C4: =分年龄阶段人口!AT4 -> 4131.8896 | D4: =分年龄阶段人口!AU4 -> 4393.4016 | E4: =分年龄阶段人口!AV4 -> 5661.7348 | F4: =分年龄阶段人口!AW4 -> 6459.3464 | G4: =分年龄阶段人口!AX4 -> 5714.0372 | H4: =分年龄阶段人口!AY4 -> 4406.4772 | I4: =SUM(B4:H4) -> 36114.807 | J4: =出生人口!B60 -> 1617 | K4: =J4*30/I4 -> 1.3432164
A5: 39082 | B5: =分年龄阶段人口!AS5 -> 5460.2185 | C5: =分年龄阶段人口!AT5 -> 4286.1249 | D5: =分年龄阶段人口!AU5 -> 4214.7487 | E5: =分年龄阶段人口!AV5 -> 5243.9865 | F5: =分年龄阶段人口!AW5 -> 6383.5092 | G5: =分年龄阶段人口!AX5 -> 6448.0502 | H5: =分年龄阶段人口!AY5 -> 4215.2745 | I5: =SUM(B5:H5) -> 36251.912 | J5: =出生人口!B61 -> 1584 | K5: =J5*30/I5 -> 1.3108274
A6: 39447 | B6: =分年龄阶段人口!AS6 -> 5166.2439 | C6: =分年龄阶段人口!AT6 -> 4452.7473 | D6: =分年龄阶段人口!AU6 -> 4386.6828 | E6: =分年龄阶段人口!AV6 -> 4901.9859 | F6: =分年龄阶段人口!AW6 -> 6474.321 | G6: =分年龄阶段人口!AX6 -> 6474.321 | H6: =分年龄阶段人口!AY6 -> 4241.3409 | I6: =SUM(B6:H6) -> 36097.643 | J6: =出生人口!B62 -> 1594 | K6: =J6*30/I6 -> 1.3247402
A7: 39813 | B7: =分年龄阶段人口!AS7 -> 4887.1136 | C7: =分年龄阶段人口!AT7 -> 4608.2294 | D7: =分年龄阶段人口!AU7 -> 4382.466 | E7: =分年龄阶段人口!AV7 -> 4661.3502 | F7: =分年龄阶段人口!AW7 -> 6228.4138 | G7: =分年龄阶段人口!AX7 -> 6427.6168 | H7: =分年龄阶段人口!AY7 -> 4807.4324 | I7: =SUM(B7:H7) -> 36002.622 | J7: =出生人口!B63 -> 1608 | K7: =J7*30/I7 -> 1.3399024
A8: 40178 | B8: =分年龄阶段人口!AS8 -> 4510.61 | C8: =分年龄阶段人口!AT8 -> 5004.375 | D8: =分年龄阶段人口!AU8 -> 4323.78 | E8: =分年龄阶段人口!AV8 -> 4577.335 | F8: =分年龄阶段人口!AW8 -> 6125.355 | G8: =分年龄阶段人口!AX8 -> 6472.325 | H8: =分年龄阶段人口!AY8 -> 5351.345 | I8: =SUM(B8:H8) -> 36365.125 | J8: =出生人口!B64 -> 1615 | K8: =J8*30/I8 -> 1.3323205
A9: 40543 | B9: =分年龄阶段人口!AS9 -> 0 | C9: =分年龄阶段人口!AT9 -> 0 | D9: =分年龄阶段人口!AU9 -> 0 | E9: =分年龄阶段人口!AV9 -> 0 | F9: =分年龄阶段人口!AW9 -> 0 | G9: =分年龄阶段人口!AX9 -> 0 | H9: =分年龄阶段人口!AY9 -> 0 | I9: =SUM(B9:H9) -> 0 | J9: =出生人口!B65 -> 1588 | K9: =J9*30/I9 -> #DIV/0!
A10: 40908 | B10: =分年龄阶段人口!AS10 -> 4513.6225 | C10: =分年龄阶段人口!AT10 -> 6278.651 | D10: =分年龄阶段人口!AU10 -> 5214.2445 | E10: =分年龄阶段人口!AV10 -> 4729.1985 | F10: =分年龄阶段人口!AW10 -> 5564.5555 | G10: =分年龄阶段人口!AX10 -> 6184.3365 | H10: =分年龄阶段人口!AY10 -> 5820.552 | I10: =SUM(B10:H10) -> 38305.16 | J10: =出生人口!B66 -> 1604 | K10: =J10*30/I10 -> 1.2562276 | L10: =J10*[1]表5全国及各地区人口年龄结构!$B$8/[1]表5全国及各地区人口年龄结构!$F$8/(1-0.242%) -> 1687.2232 | M10: =L10/I10*30 -> 1.3214067
A11: 41274 | B11: =分年龄阶段人口!AS11 -> 4211.0644 | C11: =分年龄阶段人口!AT11 -> 5984.8568 | D11: =分年龄阶段人口!AU11 -> 5375.5388 | E11: =分年龄阶段人口!AV11 -> 4942.246 | F11: =分年龄阶段人口!AW11 -> 5240.1348 | G11: =分年龄阶段人口!AX11 -> 6336.9072 | H11: =分年龄阶段人口!AY11 -> 5862.9932 | I11: =SUM(B11:H11) -> 37953.741 | J11: =出生人口!B67 -> 1635 | K11: =J11*30/I11 -> 1.2923627 | L11: =J11*[1]表5全国及各地区人口年龄结构!$B$8/[1]表5全国及各地区人口年龄结构!$F$8/(1-0.242%) -> 1719.8316 | M11: =L11/I11*30 -> 1.3594167
A12: 41639 | B12: =分年龄阶段人口!AS12 -> 3959.6952 | C12: =分年龄阶段人口!AT12 -> 5646.988 | D12: =分年龄阶段人口!AU12 -> 5646.988 | E12: =分年龄阶段人口!AV12 -> 4953.0208 | F12: =分年龄阶段人口!AW12 -> 5021.0568 | G12: =分年龄阶段人口!AX12 -> 6177.6688 | H12: =分年龄阶段人口!AY12 -> 5864.7032 | I12: =SUM(B12:H12) -> 37270.121 | J12: =出生人口!B68 -> 1640 | K12: =J12*30/I12 -> 1.3200923 | L12: =J12*[1]表5全国及各地区人口年龄结构!$B$8/[1]表5全国及各地区人口年龄结构!$F$8/(1-0.242%) -> 1725.091 | M12: =L12/I12*30 -> 1.388585
A13: 42004 | B13: =分年龄阶段人口!AS13 -> 3665.7576 | C13: =分年龄阶段人口!AT13 -> 5334.498 | D13: =分年龄阶段人口!AU13 -> 5963.6952 | E13: =分年龄阶段人口!AV13 -> 4965.1866 | F13: =分年龄阶段人口!AW13 -> 4869.4392 | G13: =分年龄阶段人口!AX13 -> 6073.1208 | H13: =分年龄阶段人口!AY13 -> 5936.3388 | I13: =SUM(B13:H13) -> 36808.036 | J13: =出生人口!B69 -> 1687 | K13: =J13*30/I13 -> 1.3749715 | L13: =J13*[1]表5全国及各地区人口年龄结构!$B$8/[1]表5全国及各地区人口年龄结构!$F$8/(1-0.242%) -> 1774.5296 | M13: =L13/I13*30 -> 1.4463116
A14: 42369 | B14: =分年龄阶段人口!AS14 -> 3477.7886 | C14: =分年龄阶段人口!AT14 -> 4811.17 | D14: =分年龄阶段人口!AU14 -> 6350.7444 | E14: =分年龄阶段人口!AV14 -> 5017.363 | F14: =分年龄阶段人口!AW14 -> 4769.9314 | G14: =分年龄阶段人口!AX14 -> 5759.6578 | H14: =分年龄阶段人口!AY14 -> 6089.5666 | I14: =SUM(B14:H14) -> 36276.222 | J14: =出生人口!B70 -> 1655 | K14: =J14*30/I14 -> 1.3686651 | L14: =J14*[1]表5全国及各地区人口年龄结构!$B$8/[1]表5全国及各地区人口年龄结构!$F$8/(1-0.242%) -> 1740.8693 | M14: =L14/I14*30 -> 1.439678
A15: 42735 | B15: =分年龄阶段人口!AS15 -> 3387.6395 | C15: =分年龄阶段人口!AT15 -> 4507.6346 | D15: =分年龄阶段人口!AU15 -> 6263.6763 | E15: =分年龄阶段人口!AV15 -> 5198.9896 | F15: =分年龄阶段人口!AW15 -> 4715.0411 | G15: =分年龄阶段人口!AX15 -> 5544.6671 | H15: =分年龄阶段人口!AY15 -> 6139.2324 | I15: =SUM(B15:H15) -> 35756.881 | J15: =出生人口!B71 -> 1786 | K15: =J15*30/I15 -> 1.4984529 | L15: =J15*[1]表5全国及各地区人口年龄结构!$B$8/[1]表5全国及各地区人口年龄结构!$F$8/(1-0.242%) -> 1878.6662 | M15: =L15/I15*30 -> 1.5761997
A16: 43100 | B16: =分年龄阶段人口!AS16 -> 3308.3904 | C16: =分年龄阶段人口!AT16 -> 4211.9424 | D16: =分年龄阶段人口!AU16 -> 5977.344 | E16: =分年龄阶段人口!AV16 -> 5365.7088 | F16: =分年龄阶段人口!AW16 -> 4934.784 | G16: =分年龄阶段人口!AX16 -> 5212.8 | H16: =分年龄阶段人口!AY16 -> 6283.1616 | I16: =SUM(B16:H16) -> 35294.131 | J16: =出生人口!B72 -> 1723 | K16: =J16*30/I16 -> 1.4645494 | L16: =J16*[1]表5全国及各地区人口年龄结构!$B$8/[1]表5全国及各地区人口年龄结构!$F$8/(1-0.242%) -> 1812.3975 | M16: =L16/I16*30 -> 1.5405372
A17: 43465 | B17: =分年龄阶段人口!AS17 -> 3251.2354 | C17: =分年龄阶段人口!AT17 -> 3893.1102 | D17: =分年龄阶段人口!AU17 -> 5511.751 | E17: =分年龄阶段人口!AV17 -> 5651.289 | F17: =分年龄阶段人口!AW17 -> 4925.6914 | G17: =分年龄阶段人口!AX17 -> 4995.4604 | H17: =分年龄阶段人口!AY17 -> 6125.7182 | I17: =SUM(B17:H17) -> 34354.256 | J17: =出生人口!B73 -> 1523 | K17: =J17*30/I17 -> 1.3299662 | L17: =J17*[1]表5全国及各地区人口年龄结构!$B$8/[1]表5全国及各地区人口年龄结构!$F$8/(1-0.242%) -> 1602.0205 | M17: =L17/I17*30 -> 1.3989712
A18: 43830 | B18: =分年龄阶段人口!AS18 -> 3276.117 | C18: =分年龄阶段人口!AT18 -> 3682.1315 | D18: =分年龄阶段人口!AU18 -> 5068.181 | E18: =分年龄阶段人口!AV18 -> 5992.214 | F18: =分年龄阶段人口!AW18 -> 4928.176 | G18: =分年龄阶段人口!AX18 -> 4844.173 | H18: =分年龄阶段人口!AY18 -> 6020.215 | I18: =SUM(B18:H18) -> 33811.207 | J18: =出生人口!B74 -> 1465 | K18: =J18*30/I18 -> 1.2998648 | L18: =J18*[1]表5全国及各地区人口年龄结构!$B$8/[1]表5全国及各地区人口年龄结构!$F$8/(1-0.242%) -> 1541.0112 | M18: =L18/I18*30 -> 1.367308
A19: 44196 | B19: =分年龄阶段人口!AS19 -> 0 | C19: =分年龄阶段人口!AT19 -> 0 | D19: =分年龄阶段人口!AU19 -> 0 | E19: =分年龄阶段人口!AV19 -> 0 | F19: =分年龄阶段人口!AW19 -> 0 | G19: =分年龄阶段人口!AX19 -> 0 | H19: =分年龄阶段人口!AY19 -> 0 | I19: =[1]表5全国及各地区人口年龄结构!$E$9/10000 -> 33003.181 | J19: =1200*12/10 -> 1440 | K19: =J19*30/I19 -> 1.3089648 | L19: =J19*[1]表5全国及各地区人口年龄结构!$B$8/[1]表5全国及各地区人口年龄结构!$F$8/(1-0.242%) -> 1514.7141 | M19: =L19/I19*30 -> 1.3768801

Sheet 分年龄阶段人口
A1: 指标名称 | B1: 抽样数:占总人口比例:0-4岁 | C1: 抽样数:占总人口比例:5-9岁 | D1: 抽样数:占总人口比例:10-14岁 | E1: 抽样数:占总人口比例:15-19岁 | F1: 抽样数:占总人口比例:20-24岁 | G1: 抽样数:占总人口比例:25-29岁 | H1: 抽样数:占总人口比例:30-34岁 | I1: 抽样数:占总人口比例:35-39岁 | J1: 抽样数:占总人口比例:40-44岁 | K1: 抽样数:占总人口比例:45-49岁 | L1: 抽样数:占总人口比例:50-54岁 | M1: 抽样数:占总人口比例:55-59岁 | N1: 抽样数:占总人口比例:60-64岁 | O1: 抽样数:占总人口比例:65-69岁 | P1: 抽样数:占总人口比例:70-74岁 | Q1: 抽样数:占总人口比例:75-79岁 | R1: 抽样数:占总人口比例:80-84岁 | S1: 抽样数:占总人口比例:85-89岁 | T1: 抽样数:占总人口比例:90-94岁 | U1: 抽样数:占总人口比例:95岁以上 | V1: 抽样数:占总人口比例:男性:0-4岁 | W1: 抽样数:占总人口比例:男性:5-9岁 | X1: 抽样数:占总人口比例:男性:10-14岁 | Y1: 抽样数:占总人口比例:男性:15-19岁 | Z1: 抽样数:占总人口比例:男性:20-24岁 | AA1: 抽样数:占总人口比例:男性:25-29岁 | AB1: 抽样数:占总人口比例:男性:30-34岁 | AC1: 抽样数:占总人口比例:男性:35-39岁 | AD1: 抽样数:占总人口比例:男性:40-44岁 | AE1: 抽样数:占总人口比例:男性:45-49岁 | AF1: 抽样数:占总人口比例:男性:50-54岁 | AG1: 抽样数:占总人口比例:男性:55-59岁 | AH1: 抽样数:占总人口比例:男性:60-64岁 | AI1: 抽样数:占总人口比例:男性:65-69岁 | AJ1: 抽样数:占总人口比例:男性:70-74岁 | AK1: 抽样数:占总人口比例:男性:75-79岁 | AL1: 抽样数:占总人口比例:男性:80-84岁 | AM1: 抽样数:占总人口比例:男性:85-89岁 | AN1: 抽样数:占总人口比例:男性:90-94岁 | AO1: 抽样数:占总人口比例:男性:95岁以上 | AP1: 抽样数:占总人口比例:女性:0-4岁 | AQ1: 抽样数:占总人口比例:女性:5-9岁 | AR1: 抽样数:占总人口比例:女性:10-14岁 | AS1: 抽样数:占总人口比例:女性:15-19岁 | AT1: 抽样数:占总人口比例:女性:20-24岁 | AU1: 抽样数:占总人口比例:女性:25-29岁 | AV1: 抽样数:占总人口比例:女性:30-34岁 | AW1: 抽样数:占总人口比例:女性:35-39岁 | AX1: 抽样数:占总人口比例:女性:40-44岁 | AY1: 抽样数:占总人口比例:女性:45-49岁 | AZ1: 抽样数:占总人口比例:女性:50-54岁 | BA1: 抽样数:占总人口比例:女性:55-59岁 | BB1: 抽样数:占总人口比例:女性:60-64岁 | BC1: 抽样数:占总人口比例:女性:65-69岁 | BD1: 抽样数:占总人口比例:女性:70-74岁 | BE1: 抽样数:占总人口比例:女性:75-79岁 | BF1: 抽样数:占总人口比例:女性:80-84岁 | BG1: 抽样数:占总人口比例:女性:85-89岁 | BH1: 抽样数:占总人口比例:女性:90-94岁 | BI1: 抽样数:占总人口比例:女性:95岁以上
A2: 37986 | B2: =original!B58/100*original!$BK58 -> 6525.9635 | C2: =original!C58/100*original!$BK58 -> 8477.2912 | D2: =original!D58/100*original!$BK58 -> 11320.285 | E2: =original!E58/100*original!$BK58 -> 10816.3 | F2: =original!F58/100*original!$BK58 -> 8774.5133 | G2: =original!G58/100*original!$BK58 -> 9821.252 | H2: =original!H58/100*original!$BK58 -> 12547.942 | I2: =original!I58/100*original!$BK58 -> 12418.715 | ... BI2: =original!BI58/100*original!$BK58 -> 12.9227
A3: 38352 | B3: =original!B59/100*original!$BK59 -> 6434.406 | C3: =original!C59/100*original!$BK59 -> 7916.2692 | D3: =original!D59/100*original!$BK59 -> 10789.004 | E3: =original!E59/100*original!$BK59 -> 11334.954 | F3: =original!F59/100*original!$BK59 -> 8254.238 | G3: =original!G59/100*original!$BK59 -> 9177.1528 | H3: =original!H59/100*original!$BK59 -> 12231.871 | I3: =original!I59/100*original!$BK59 -> 12712.826 | ... BI3: =original!BI59/100*original!$BK59 -> 12.9988
A4: 38717 | B4: =original!B60/100*original!$BK60 -> 6982.3704 | C4: =original!C60/100*original!$BK60 -> 8159.1744 | D4: =original!D60/100*original!$BK60 -> 10421.253 | E4: =original!E60/100*original!$BK60 -> 11114.26 | F4: =original!F60/100*original!$BK60 -> 7976.116 | G4: =original!G60/100*original!$BK60 -> 8551.4424 | H4: =original!H60/100*original!$BK60 -> 11127.336 | I4: =original!I60/100*original!$BK60 -> 12709.483 | ... BI4: =original!BI60/100*original!$BK60 -> 19.351888
A5: 39082 | B5: =original!B61/100*original!$BK61 -> 6674.1408 | C5: =original!C61/100*original!$BK61 -> 7779.7499 | D5: =original!D61/100*original!$BK61 -> 9824.0292 | E5: =original!E61/100*original!$BK61 -> 11574.917 | F5: =original!F61/100*original!$BK61 -> 8393.8749 | G5: =original!G61/100*original!$BK61 -> 8167.9158 | H5: =original!H61/100*original!$BK61 -> 10293.693 | I5: =original!I61/100*original!$BK61 -> 12559.068 | ... BI5: =original!BI61/100*original!$BK61 -> 0
A6: 39447 | B6: =original!B62/100*original!$BK62 -> 6672.5145 | C6: =original!C62/100*original!$BK62 -> 7584.2046 | D6: =original!D62/100*original!$BK62 -> 9367.9461 | E6: =original!E62/100*original!$BK62 -> 10993.133 | F6: =original!F62/100*original!$BK62 -> 8733.7269 | G6: =original!G62/100*original!$BK62 -> 8535.5334 | H6: =original!H62/100*original!$BK62 -> 9645.417 | I6: =original!I62/100*original!$BK62 -> 12829.726 | ... BI6: =original!BI62/100*original!$BK62 -> 26.4258
A7: 39813 | B7: =original!B63/100*original!$BK63 -> 6812.7426 | C7: =original!C63/100*original!$BK63 -> 7250.9892 | D7: =original!D63/100*original!$BK63 -> 8937.5746 | E7: =original!E63/100*original!$BK63 -> 10451.517 | F7: =original!F63/100*original!$BK63 -> 9110.2172 | G7: =original!G63/100*original!$BK63 -> 8605.5696 | H7: =original!H63/100*original!$BK63 -> 9243.0192 | I7: =original!I63/100*original!$BK63 -> 12310.745 | ... BI7: =original!BI63/100*original!$BK63 -> 26.5604
A8: 40178 | B8: =original!B64/100*original!$BK64 -> 6886.02 | C8: =original!C64/100*original!$BK64 -> 7219.645 | D8: =original!D64/100*original!$BK64 -> 8407.35 | E8: =original!E64/100*original!$BK64 -> 9568.365 | F8: =original!F64/100*original!$BK64 -> 10035.44 | G8: =original!G64/100*original!$BK64 -> 8647.56 | H8: =original!H64/100*original!$BK64 -> 9021.22 | I8: =original!I64/100*original!$BK64 -> 12143.95 | ... BI8: =original!BI64/100*original!$BK64 -> 26.69
A9: 40543 | B9: =original!B65/100*original!$BK65 -> 0 | C9: =original!C65/100*original!$BK65 -> 0 | D9: =original!D65/100*original!$BK65 -> 0 | E9: =original!E65/100*original!$BK65 -> 0 | F9: =original!F65/100*original!$BK65 -> 0 | G9: =original!G65/100*original!$BK65 -> 0 | H9: =original!H65/100*original!$BK65 -> 0 | I9: =original!I65/100*original!$BK65 -> 0 | ... BI9: =original!BI65/100*original!$BK65 -> 0
A10: 40908 | B10: =original!B66/100*original!$BK66 -> 7626.001 | C10: =original!C66/100*original!$BK66 -> 7208.3225 | D10: =original!D66/100*original!$BK66 -> 7356.531 | E10: =original!E66/100*original!$BK66 -> 9458.397 | F10: =original!F66/100*original!$BK66 -> 12772.878 | G10: =original!G66/100*original!$BK66 -> 10495.856 | H10: =original!H66/100*original!$BK66 -> 9660.4995 | I10: =original!I66/100*original!$BK66 -> 11398.581 | ... BI10: =original!BI66/100*original!$BK66 -> 26.947
A11: 41274 | B11: =original!B67/100*original!$BK67 -> 7704.4876 | C11: =original!C67/100*original!$BK67 -> 7379.518 | D11: =original!D67/100*original!$BK67 -> 7203.4928 | E11: =original!E67/100*original!$BK67 -> 8896.0428 | F11: =original!F67/100*original!$BK67 -> 12254.062 | G11: =original!G67/100*original!$BK67 -> 10832.32 | H11: =original!H67/100*original!$BK67 -> 10060.517 | I11: =original!I67/100*original!$BK67 -> 10723.997 | ... BI11: =original!BI67/100*original!$BK67 -> 27.0808
A12: 41639 | B12: =original!B68/100*original!$BK68 -> 7728.8896 | C12: =original!C68/100*original!$BK68 -> 7592.8176 | D12: =original!D68/100*original!$BK68 -> 7007.708 | E12: =original!E68/100*original!$BK68 -> 8354.8208 | F12: =original!F68/100*original!$BK68 -> 11851.871 | G12: =original!G68/100*original!$BK68 -> 11334.798 | H12: =original!H68/100*original!$BK68 -> 10055.721 | I12: =original!I68/100*original!$BK68 -> 10259.829 | ... BI12: =original!BI68/100*original!$BK68 -> 27.2144
A13: 42004 | B13: =original!B69/100*original!$BK69 -> 7782.8958 | C13: =original!C69/100*original!$BK69 -> 7673.4702 | D13: =original!D69/100*original!$BK69 -> 7085.3076 | E13: =original!E69/100*original!$BK69 -> 7878.6432 | F13: =original!F69/100*original!$BK69 -> 11038.307 | G13: =original!G69/100*original!$BK69 -> 12023.138 | H13: =original!H69/100*original!$BK69 -> 10039.799 | I13: =original!I69/100*original!$BK69 -> 9944.0514 | ... BI13: =original!BI69/100*original!$BK69 -> 27.3564
... A18: 43830 | B18: =original!B74/100*original!$BK74 -> 8036.287 | C18: =original!C74/100*original!$BK74 -> 7784.278 | D18: =original!D74/100*original!$BK74 -> 7672.274 | E18: =original!E74/100*original!$BK74 -> 7154.2555 | F18: =original!F74/100*original!$BK74 -> 7882.2815 | G18: =original!G74/100*original!$BK74 -> 10486.374 | H18: =original!H74/100*original!$BK74 -> 12054.431 | I18: =original!I74/100*original!$BK74 -> 9968.356 | ... BI18: =original!BI74/100*original!$BK74 -> 42.0015
A19: 44196 | B19: =[1]表5全国及各地区人口年龄结构!$B$8*B18/SUM($B18:$D18)/10000 -> 8667.6031 | C19: =[1]表5全国及各地区人口年龄结构!$B$8*C18/SUM($B18:$D18)/10000 -> 8395.7968 | D19: =[1]表5全国及各地区人口年龄结构!$B$8*D18/SUM($B18:$D18)/10000 -> 8274.9939 | E19: =[1]表5全国及各地区人口年龄结构!$B$9*E18/SUM($E18:$M18)/10000 -> 7021.4495 | F19: =[1]表5全国及各地区人口年龄结构!$B$9*F18/SUM($E18:$M18)/10000 -> 7735.961 | G19: =[1]表5全国及各地区人口年龄结构!$B$9*G18/SUM($E18:$M18)/10000 -> 10291.714 | H19: =[1]表5全国及各地区人口年龄结构!$B$9*H18/SUM($E18:$M18)/10000 -> 11830.661 | I19: =[1]表5全国及各地区人口年龄结构!$B$9*I18/SUM($E18:$M18)/10000 -> 9783.3112 | J19: =[1]表5全国及各地区人口年龄结构!$B$9*J18/SUM($E18:$M18)/10000 -> 9700.8676 | K19: =[1]表5全国及各地区人口年龄结构!$B$9*K18/SUM($E18:$M18)/10000 -> 12036.771 | L19: =[1]表5全国及各地区人口年龄结构!$B$9*L18/SUM($E18:$M18)/10000 -> 11720.737 | M19: =[1]表5全国及各地区人口年龄结构!$B$9*M18/SUM($E18:$M18)/10000 -> 9316.1306 | N19: =([1]表5全国及各地区人口年龄结构!$B$10-[1]表5全国及各地区人口年龄结构!$B$11)/10000 -> 7338.3486 | O19: =[1]表5全国及各地区人口年龄结构!$B$11*O18/SUM($O18:$U18)/10000 -> 7658.7762 | P19: =[1]表5全国及各地区人口年龄结构!$B$11*P18/SUM($O18:$U18)/10000 -> 4959.2471 | Q19: =[1]表5全国及各地区人口年龄结构!$B$11*Q18/SUM($O18:$U18)/10000 -> 3139.3399 | R19: =[1]表5全国及各地区人口年龄结构!$B$11*R18/SUM($O18:$U18)/10000 -> 1986.732 | S19: =[1]表5全国及各地区人口年龄结构!$B$11*S18/SUM($O18:$U18)/10000 -> 970.61718 | T19: =[1]表5全国及各地区人口年龄结构!$B$11*T18/SUM($O18:$U18)/10000 -> 288.15197 | U19: =[1]表5全国及各地区人口年龄结构!$B$11*U18/SUM($O18:$U18)/10000 -> 60.663574 | V19: =original!V75/100*original!$BK75 -> 0 | W19: =original!W75/100*original!$BK75 -> 0 | X19: =original!X75/100*original!$BK75 -> 0 | Y19: =original!Y75/100*original!$BK75 -> 0 | Z19: =original!Z75/100*original!$BK75 -> 0 | AA19: =original!AA75/100*original!$BK75 -> 0 | AB19: =original!AB75/100*original!$BK75 -> 0 | AC19: =original!AC75/100*original!$BK75 -> 0 | ... BI19: =original!BI75/100*original!$BK75 -> 0

Sheet original
A1: 指标名称 | B1: 抽样数:占总人口比例:0-4岁 | C1: 抽样数:占总人口比例:5-9岁 | D1: 抽样数:占总人口比例:10-14岁 | E1: 抽样数:占总人口比例:15-19岁 | F1: 抽样数:占总人口比例:20-24岁 | G1: 抽样数:占总人口比例:25-29岁 | H1: 抽样数:占总人口比例:30-34岁 | I1: 抽样数:占总人口比例:35-39岁 | J1: 抽样数:占总人口比例:40-44岁 | K1: 抽样数:占总人口比例:45-49岁 | L1: 抽样数:占总人口比例:50-54岁 | M1: 抽样数:占总人口比例:55-59岁 | N1: 抽样数:占总人口比例:60-64岁 | O1: 抽样数:占总人口比例:65-69岁 | P1: 抽样数:占总人口比例:70-74岁 | Q1: 抽样数:占总人口比例:75-79岁 | R1: 抽样数:占总人口比例:80-84岁 | S1: 抽样数:占总人口比例:85-89岁 | T1: 抽样数:占总人口比例:90-94岁 | U1: 抽样数:占总人口比例:95岁以上 | V1: 抽样数:占总人口比例:男性:0-4岁 | W1: 抽样数:占总人口比例:男性:5-9岁 | X1: 抽样数:占总人口比例:男性:10-14岁 | Y1: 抽样数:占总人口比例:男性:15-19岁 | Z1: 抽样数:占总人口比例:男性:20-24岁 | AA1: 抽样数:占总人口比例:男性:25-29岁 | AB1: 抽样数:占总人口比例:男性:30-34岁 | AC1: 抽样数:占总人口比例:男性:35-39岁 | AD1: 抽样数:占总人口比例:男性:40-44岁 | AE1: 抽样数:占总人口比例:男性:45-49岁 | AF1: 抽样数:占总人口比例:男性:50-54岁 | AG1: 抽样数:占总人口比例:男性:55-59岁 | AH1: 抽样数:占总人口比例:男性:60-64岁 | AI1: 抽样数:占总人口比例:男性:65-69岁 | AJ1: 抽样数:占总人口比例:男性:70-74岁 | AK1: 抽样数:占总人口比例:男性:75-79岁 | AL1: 抽样数:占总人口比例:男性:80-84岁 | AM1: 抽样数:占总人口比例:男性:85-89岁 | AN1: 抽样数:占总人口比例:男性:90-94岁 | AO1: 抽样数:占总人口比例:男性:95岁以上 | AP1: 抽样数:占总人口比例:女性:0-4岁 | AQ1: 抽样数:占总人口比例:女性:5-9岁 | AR1: 抽样数:占总人口比例:女性:10-14岁 | AS1: 抽样数:占总人口比例:女性:15-19岁 | AT1: 抽样数:占总人口比例:女性:20-24岁 | AU1: 抽样数:占总人口比例:女性:25-29岁 | AV1: 抽样数:占总人口比例:女性:30-34岁 | AW1: 抽样数:占总人口比例:女性:35-39岁 | AX1: 抽样数:占总人口比例:女性:40-44岁 | AY1: 抽样数:占总人口比例:女性:45-49岁 | AZ1: 抽样数:占总人口比例:女性:50-54岁 | BA1: 抽样数:占总人口比例:女性:55-59岁 | BB1: 抽样数:占总人口比例:女性:60-64岁 | BC1: 抽样数:占总人口比例:女性:65-69岁 | BD1: 抽样数:占总人口比例:女性:70-74岁 | BE1: 抽样数:占总人口比例:女性:75-79岁 | BF1: 抽样数:占总人口比例:女性:80-84岁 | BG1: 抽样数:占总人口比例:女性:85-89岁 | BH1: 抽样数:占总人口比例:女性:90-94岁 | BI1: 抽样数:占总人口比例:女性:95岁以上 | BJ1: 总人口 | BK1: 总人口
A2: 频率 | B2: 年 | C2: 年 | D2: 年 | E2: 年 | F2: 年 | G2: 年 | H2: 年 | I2: 年 | J2: 年 | K2: 年 | L2: 年 | M2: 年 | N2: 年 | O2: 年 | P2: 年 | Q2: 年 | R2: 年 | S2: 年 | T2: 年 | U2: 年 | V2: 年 | W2: 年 | X2: 年 | Y2: 年 | Z2: 年 | AA2: 年 | AB2: 年 | AC2: 年 | AD2: 年 | AE2: 年 | AF2: 年 | AG2: 年 | AH2: 年 | AI2: 年 | AJ2: 年 | AK2: 年 | AL2: 年 | AM2: 年 | AN2: 年 | AO2: 年 | AP2: 年 | AQ2: 年 | AR2: 年 | AS2: 年 | AT2: 年 | AU2: 年 | AV2: 年 | AW2: 年 | AX2: 年 | AY2: 年 | AZ2: 年 | BA2: 年 | BB2: 年 | BC2: 年 | BD2: 年 | BE2: 年 | BF2: 年 | BG2: 年 | BH2: 年 | BI2: 年 | BJ2: 年 | BK2: 年
A3: 单位 | B3: % | C3: % | D3: % | E3: % | F3: % | G3: % | H3: % | I3: % | J3: % | K3: % | L3: % | M3: % | N3: % | O3: % | P3: % | Q3: % | R3: % | S3: % | T3: % | U3: % | V3: % | W3: % | X3: % | Y3: % | Z3: % | AA3: % | AB3: % | AC3: % | AD3: % | AE3: % | AF3: % | AG3: % | AH3: % | AI3: % | AJ3: % | AK3: % | AL3: % | AM3: % | AN3: % | AO3: % | AP3: % | AQ3: % | AR3: % | AS3: % | AT3: % | AU3: % | AV3: % | AW3: % | AX3: % | AY3: % | AZ3: % | BA3: % | BB3: % | BC3: % | BD3: % | BE3: % | BF3: % | BG3: % | BH3: % | BI3: % | BJ3: 万人 | BK3: 万人
A4: 18263 | BK4: 54167
A5: 18628 | BK5: 55196
A6: 18993 | BK6: 56300
A7: 19359 | BK7: 57482
A8: 19724 | BJ8: 59435 | BK8: 58796
A9: 20089 | BK9: 60266
A10: 20454 | BK10: 61465
A11: 20820 | BK11: 62828
A12: 21185 | BK12: 64653
A13: 21550 | BK13: 65994
A14: 21915 | BK14: 67207
A15: 22281 | BK15: 66207
A16: 22646 | BK16: 65859
A17: 23011 | BK17: 67295
A18: 23376 | BK18: 69172
A19: 23742 | BJ19: 69458 | BK19: 70499
A20: 24107 | BK20: 72538
A21: 24472 | BK21: 74542
A22: 24837 | BK22: 76368
A23: 25203 | BK23: 78534
A24: 25568 | BK24: 80671
A25: 25933 | BK25: 82992
A26: 26298 | BK26: 85229
A27: 26664 | BK27: 87177
A28: 27029 | BK28: 89211
A29: 27394 | BK29: 90859
A30: 27759 | BK30: 92420
A31: 28125 | BK31: 93717
... A36: 29951 | BK36: 100072
A37: 30316 | BJ37: 100818 | BK37: 101654
A38: 30681 | BK38: 103008
A39: 31047 | BK39: 104357
A40: 31412 | BK40: 105851
A41: 31777 | BK41: 107507
A42: 32142 | BK42: 109300
A43: 32508 | BK43: 111026
A44: 32873 | BK44: 112704
...

Sheet 出生人口
A1: 指标名称 | B1: 出生人数
A2: 频率 | B2: 年
A3: 单位 | B3: 万人
A4: 18263 | B4: 1950
A5: 18628 | B5: 2042
A6: 18993 | B6: 2128
A7: 19359 | B7: 2127
A8: 19724 | B8: 2175
A9: 20089 | B9: 2288
A10: 20454 | B10: 2004
A11: 20820 | B11: 2004 | C11: =C12+1 -> 64
A12: 21185 | B12: 2200 | C12: =C13+1 -> 63
A13: 21550 | B13: 1928 | C13: =C14+1 -> 62
A14: 21915 | B14: 1665 | C14: =C15+1 -> 61
A15: 22281 | B15: 1381 | C15: =C16+1 -> 60
A16: 22646 | B16: 1187 | C16: =C17+1 -> 59
A17: 23011 | B17: 2491 | C17: =C18+1 -> 58
A18: 23376 | B18: 3000 | C18: =C19+1 -> 57
A19: 23742 | B19: 2759 | C19: =C20+1 -> 56
A20: 24107 | B20: 2748 | C20: =C21+1 -> 55
A21: 24472 | B21: 2795 | C21: =C22+1 -> 54
A22: 24837 | B22: 2593 | C22: =C23+1 -> 53
... A74: 43830 | B74: 1465 | C74: =C75+1 -> 1
B75: =育龄妇女TFR!J19 -> 1440 | C75: 0
